Workbook

Sheet Call-lijst
A1: SPORT 2000 NEDERLAND · COLDCALL
A2: ="Peildatum 27-10-2026 · "&COUNTA($C$6:$C$54)&" winkels · Nu doen: "&(COUNTIF($B$6:$B$54,"OPVOLGEN")+COUNTIF($B$6:$B$54,"BELLEN")+COUNTIF($B$6:$B$54,"MAILEN")+COUNTIF($B$6:$B$54,"EERSTE BENADERING"))&" (opvolgen "&COUNTIF($B$6:$B$54,"OPVOLGEN")&", bellen "&COUNTIF($B$6:$B$54,"BELLEN")&", mailen "&COUNTIF($B$6:$B$54,"MAILEN")&", eerste benadering "&COUNTIF($B$6:$B$54,"EERSTE BENADERING")&") · Wachten/later: "&(COUNTIF($B$6:$B$54,"WACHTEN")+COUNTIF($B$6:$B$54,"LATER"))&" · Klant: "&COUNTIF($B$6:$B$54,"KLANT")
B3: OPVOLGEN | C3: BELLEN | D3: MAILEN | F3: WACHTEN | G3: EERSTE BENADERING | H3: LATER | I3: KLANT | J3: NIET BENADEREN
B4: Reminder of feedback vragen | C4: Nu bellen | D4: Nu mailen | F4: Zij zijn aan zet | G4: Bellen, daarna mailen | H4: Op het genoemde moment | I4: Relatie onderhouden | J4: Nooit meer benaderen
A5: # | B5: Volgende actie | C5: Naam | D5: Plaats | E5: Regio | F5: Status | G5: Wanneer | H5: Wat nu | I5: Contactpersoon | J5: Telefoon | K5: E-mail | L5: Laatste contact | M5: Dagen geleden | N5: Wat is er gedaan | O5: Producten / specialisatie | P5: Adres | Q5: Provincie | R5: Formule | S5: Opmerking | T5: Volledige historie | U5: Winkelpagina
A6: 1 | B6: OPVOLGEN | C6: Sport 2000 Heerhugowaard | D6: Heerhugowaard | E6: West | F6: Gemaild / Gebeld | G6: Nu | H6: Reminder sturen of bellen | I6: info@sport2000heerhugowaard.nl | J6: 072-5722779 | K6: info@sport2000heerhugowaard.nl | M6: =IF(L6="","",TODAY()-L6) | N6: Gemaild/gebeld volgens sheet, info@-adres genoteerd. Geen reactie vermeld. | O6: Tennis, handbal, hardlopen, hockey, voetbal, fitness | P6: Middenwaard 48 b, 1703 SH | Q6: Noord-Holland | R6: Sport 2000 | T6: Retail-sheet: gemarkeerd 'Gemaild / Gebeld', info@-adres genoteerd | U6: https://www.sport2000.nl/nl/vind-een-winkel/details/sport-2000-heerhugowaard/
A7: 2 | B7: OPVOLGEN | C7: Sport 2000 Sportshop Bouwes Schagen | D7: Schagen | E7: West | F7: Positieve lead | G7: Nu | H7: Feedback op samples vragen; bellen als het stil blijft. Lead in Bigin | I7: Michel van der Wardt; michel@sportshopbouwes.nl | J7: 0224 - 296697 | K7: info@sportshopbouwes.nl | L7: 46297 | M7: =IF(L7="","",TODAY()-L7) | N7: Samples bezorgd 23-09. Michel (bedrijfsleider) 02-10: collega test, 'je hoort snel van mij'. | O7: Voetbal, casual, indoor (hanbal en volleybal), winter, running, fitness, tennis. | P7: Gedempte Gracht 34, 1741 GC | Q7: Noord-Holland | R7: Sport 2000 | S7: Blauw gemarkeerd in Timo's lijst (betekenis nog te bevestigen) | T7: Mailbox info@ (27-10-2026): samples gevraagd 19-09-2026 door Michel van der Wardt (bedrijfsleider); pakket bezorgd 23-09 (MyParcel); nabel-mail 30-09; 02-10-2026 Michel: collega test de sokken, 'je hoort snel van mij' | U7: https://www.sport2000.nl/nl/vind-een-winkel/details/sport-2000-sportshop-bouwes-schagen/
A8: 3 | B8: OPVOLGEN | C8: Sport 2000 Parkstad Kerkrade | D8: Kerkrade | E8: Zuid | F8: Gemaild / Gebeld | G8: Nu | H8: Opvolgen bij Melvin of Raymond | I8: Melvin; raymond@sport2000parkstad.nl | J8: 045-5421855 | K8: info@sport2000parkstad.nl | M8: =IF(L8="","",TODAY()-L8) | N8: Gesproken met Melvin, mail naar Raymond. Geen vervolg vermeld. | O8: Voetbal, Running, Fitness, Teamwear en bedrukking, Bedrijfskleding, Casual, Outdoor, Wandel, Fietskleding, Wintersportkleding | P8: Wiebachstraat 77A, 6466 NG | Q8: Limburg | R8: Sport 2000 | S8: Blauw gemarkeerd in Timo's lijst (betekenis nog te bevestigen) | T8: Retail-sheet: gemarkeerd 'Gemaild / Gebeld', gesproken met Melvin, mail naar raymond@ | U8: https://www.sport2000.nl/nl/vind-een-winkel/details/sport-2000-parkstad-kerkrade/
A9: 4 | B9: BELLEN | C9: Sport 2000 Appingedam | D9: Appingedam | E9: Noord | F9: Bellen | G9: Nu | H9: Bellen | J9: 0596-680544 | K9: sporthuismossel@home.nl | M9: =IF(L9="","",TODAY()-L9) | N9: Sheet: 'dinsdag bellen'. Verder geen contact gevonden. | O9: Breed sportassortiment (indicatief; niet gepubliceerd per winkel) | P9: Dijkstraat 72-74, 9901 AV | Q9: Groningen | R9: Sport 2000 | T9: Retail-sheet: 'DINSDAG BELLEN'. Timo's lijst: 'heel veel paar' | U9: https://www.sport2000.nl/nl/vind-een-winkel/details/sport-2000-appingedam/
A10: 5 | B10: BELLEN | C10: Absolute Teamsport Free-Kick Den Haag | D10: Den Haag | E10: West | F10: Bellen | G10: Nu | H10: Bellen, vragen naar Carlo | I10: Carlo | J10: 070-3636323 | K10: sport@free-kick.nl | M10: =IF(L10="","",TODAY()-L10) | N10: Timo's lijst: 'Morgen bellen, Carlo'. | O10: Voetbal, casual, hockey | P10: De Savornin Lohmanplein 45 A, 2566 AE | Q10: Zuid-Holland | R10: Absolute Teamsport | T10: Timo's lijst: 'Morgen bellen, Carlo' | U10: https://www.sport2000.nl/nl/vind-een-winkel/details/absolute-teamsport-free-kick-den-haag/
A11: 6 | B11: BELLEN | C11: Sport 2000 L.J. Sport Lisse | D11: Lisse | E11: West | F11: Bellen | G11: Nu | H11: Opnieuw bellen, Patrick vragen | I11: Patrick | J11: 0252-240777 | K11: info@ljsport.nl | M11: =IF(L11="","",TODAY()-L11) | N11: Gebeld met Patrick (inkoop): 'heel druk'. | O11: Voetbal, Tennis, Hardlopen, Fitness, Hockey, Zaalsporten, Outdoor en Teamsport en Teamwear. | P11: Kanaalstraat 76, 2161 JN | Q11: Zuid-Holland | R11: Sport 2000 | T11: Retail-sheet: gebeld met Patrick (gaat over inkoop), gaf aan 'heel druk te zijn' | U11: https://www.sport2000.nl/nl/vind-een-winkel/details/sport-2000-lj-sport-lisse/
A12: 7 | B12: BELLEN | C12: Sport 2000 Spijkenisse | D12: Spijkenisse | E12: West | F12: Nu geen interesse, later opnieuw benaderen | G12: Nu (okt/nov) | H12: Nu opnieuw bellen, dit was het genoemde moment | J12: 0181-623743 | K12: info@sport2000spijkenisse.nl | L12: 45836 | M12: =IF(L12="","",TODAY()-L12) | N12: Gebeld 26-06-2025: toen geen behoefte, 'okt/nov wel interessant'. Mail 28-06-2025. | O12: Tennis, hardlopen, hockey, voetbal, fitness | P12: Uitstraat 113, 3201 EN | Q12: Zuid-Holland | R12: Sport 2000 | T12: Mailbox info@ (27-10-2026): gebeld do 26-06-2025: geen behoefte nu, 'rond oktober/november wel interessant'; mail 28-06-2025 (Tigo, sales@) | U12: https://www.sport2000.nl/nl/vind-een-winkel/details/sport-2000-spijkenisse/
A13: 8 | B13: BELLEN | C13: Sport 2000 Voorburg | D13: Voorburg | E13: West | F13: Reminder gestuurd | G13: Nu | H13: Opnieuw bellen, vragen naar Thijs of Jesper | I13: Thijs, Jesper | J13: 070-3861866 | K13: info@sport2000voorburg.nl | L13: 45866 | M13: =IF(L13="","",TODAY()-L13) | N13: Gebeld 26-06-2025, mail 28-06, reminder 28-07-2025. Geen reactie. Thijs en Jesper zouden kijken. | O13: Voetbal, hockey, tennis, hardlopen, fitness/indoor | P13: Koningin Julianaplein 14b, 2274 JD | Q13: Zuid-Holland | R13: Sport 2000 | T13: Mailbox info@ (27-10-2026): gebeld do 26-06-2025 (Thijs en Jesper zouden kijken); mail 28-06-2025; reminder 28-07-2025; geen reactie gevonden | U13: https://www.sport2000.nl/nl/vind-een-winkel/details/sport-2000-voorburg/
A14: 9 | B14: BELLEN | C14: Sport 2000 Akwi Sport Eindhoven | D14: Eindhoven | E14: Zuid | F14: Reminder gestuurd | G14: Nu | H14: Bellen | J14: 040 2451893 | K14: info@akwisport.nl | L14: 46201 | M14: =IF(L14="","",TODAY()-L14) | N14: Gebeld 17-06, gemaild 18-06, reminder 28-06-2026. Geen reactie. | O14: Tennis, Voetbal, Padel, Fitness, Running en Indoor | P14: Tongelresestraat 266, 5613 DV | Q14: Noord-Brabant | R14: Sport 2000 | T14: Mailbox info@ (27-10-2026): gebeld wo 17-06-2026 (collega); mail 18-06-2026; reminder 28-06-2026 (tigo@, cc info@); geen reactie gevonden | U14: https://www.sport2000.nl/nl/vind-een-winkel/details/sport-2000-akwi-sport-eindhoven/
A15: 10 | B15: MAILEN | C15: Absolute Teamsport Leugemors Winterswijk | D15: Winterswijk | E15: Oost | F15: Mailen | G15: Nu | H15: Mailen | I15: verkoop@sport2000leugemors.nl (extra adres uit Timo's lijst) | J15: 0543-512419 | K15: info@atsleugemors.nl | M15: =IF(L15="","",TODAY()-L15) | N15: Staat als 'mailen' in Timo's lijst. Niets verstuurd gevonden in info@. | O15: Voetbal, fitness, running, tennis, zaalsport | P15: Misterstraat 11, 7101 EN | Q15: Gelderland | R15: Absolute Teamsport | T15: Timo's lijst: 'mailen' | U15: https://www.sport2000.nl/nl/vind-een-winkel/details/absolute-teamsport-leugemors-winterswijk/
A16: 11 | B16: MAILEN | C16: Sport 2000 Bart Langedijk Den Helder | D16: Den Helder | E16: West | F16: Mailen | G16: Nu | H16: Mailen, aanspreken op Bart | I16: Bart | J16: 022-3694961 | K16: info@bartlangedijk.nl | M16: =IF(L16="","",TODAY()-L16) | N16: Staat als 'mailen' in Timo's lijst, contact Bart. Niets verstuurd gevonden. | O16: Voetbal, Running, Wandelen, Crossfit, Tennis, Handbal en Zwemmen | P16: Beatrixstraat 60, 1781 EP | Q16: Noord-Holland | R16: Sport 2000 | T16: Timo's lijst: 'mailen', contact Bart | U16: https://www.sport2000.nl/nl/vind-een-winkel/details/sport-2000-bart-langedijk-den-helder/
A17: 12 | B17: MAILEN | C17: Absolute Teamsport Haarlem | D17: Haarlem | E17: West | F17: Mailen | G17: Nu | H17: Mailen | J17: 023-5511955 | K17: info@absolutetshaarlem.nl | M17: =IF(L17="","",TODAY()-L17) | N17: Staat als 'mailen' in Timo's lijst. Niets verstuurd gevonden. | O17: Voetbal, Casual | P17: Generaal Cronjéstraat 16, 2021 JH | Q17: Noord-Holland | R17: Absolute Teamsport | T17: Timo's lijst: 'mailen' | U17: https://www.sport2000.nl/nl/vind-een-winkel/details/absolute-teamsport-haarlem/
A18: 13 | B18: MAILEN | C18: Absolute Teamsport Purmerend | D18: Purmerend | E18: West | F18: Mailen | G18: Nu | H18: Mailen, Frank benaderen | I18: Frank | J18: 0299787520 | K18: info@absolutepurmerend.nl | M18: =IF(L18="","",TODAY()-L18) | N18: Staat als 'mailen' in Timo's lijst, contact Frank. Niets verstuurd gevonden. | O18: Voetbal, Clubkleding , Casual en Lifestyle | P18: Hoogstraat 9-13, 1441 BB | Q18: Noord-Holland | R18: Absolute Teamsport | T18: Timo's lijst: 'mailen', contact Frank, 'vrijdag' | U18: https://www.sport2000.nl/nl/vind-een-winkel/details/absolute-teamsport-purmerend/
A19: 14 | B19: WACHTEN | C19: Sport 2000 Boxmeer | D19: Boxmeer | E19: Zuid | F19: Bellen ons (terugbellen door hen) | G19: Wacht op hen | H19: Nabellen als zij niet terugbellen | J19: 0485-571661 | K19: info@sport2000boxmeer.nl | M19: =IF(L19="","",TODAY()-L19) | N19: Gebeld: inkoper in gesprek, 'Inkoop belt ons'. | O19: Voetbal, tennis, fitness, hockey, hardlopen, wandelen. | P19: D'n Entrepot 5, 5831 DE | Q19: Noord-Brabant | R19: Sport 2000 | T19: Retail-sheet: gebeld, inkoper was in gesprek, 'Inkoop belt ons' | U19: https://www.sport2000.nl/nl/vind-een-winkel/details/sport-2000-boxmeer/
A20: 15 | B20: EERSTE BENADERING | C20: Sport 2000 Combi-Sport Beilen | D20: Beilen | E20: Noord | F20: Nog niet benaderd | G20: Nu | H20: Bellen, daarna mailen | J20: 0593-525466 | K20: info@combisport.nl | M20: =IF(L20="","",TODAY()-L20) | N20: Nog geen contact gevonden (sheet en mailbox info@). | O20: Voetbal, Indoor, Running, Fitness, Zwemmen | P20: Brinkstraat 33, 9411 KK | Q20: Drenthe | R20: Sport 2000 | U20: https://www.sport2000.nl/nl/vind-een-winkel/details/sport-2000-combi-sport-beilen/
A21: 16 | B21: EERSTE BENADERING | C21: Sport 2000 Sporthuis A.P. Van Der Feer | D21: Bolsward | E21: Noord | F21: Nog niet benaderd | G21: Nu | H21: Bellen, daarna mailen | J21: 0515-572397 | K21: feersport@planet.nl | M21: =IF(L21="","",TODAY()-L21) | N21: Nog geen contact gevonden (sheet en mailbox info@). | O21: Wintersport, wielrennen, voetbal, tennis, sportprijzen. | P21: Dijkstraat 7-11, 8701 KB | Q21: Friesland | R21: Sport 2000 | U21: https://www.sport2000.nl/nl/vind-een-winkel/details/sport-2000-sporthuis-ap-van-der-feer/
A22: 17 | B22: EERSTE BENADERING | C22: Sport 2000 De Jonge Sport Stadskanaal | D22: Stadskanaal | E22: Noord | F22: Nog niet benaderd | G22: Nu | H22: Bellen, daarna mailen | J22: 0599-618024 | K22: dejongesport@xs4all.nl | M22: =IF(L22="","",TODAY()-L22) | N22: Nog geen contact gevonden (sheet en mailbox info@). | O22: Voetbal, hardlopen, tennis, badmode, winterpsort | P22: Europalaan 40, 9501 CW | Q22: Groningen | R22: Sport 2000 | S22: Blauw gemarkeerd in Timo's lijst (betekenis nog te bevestigen) | U22: https://www.sport2000.nl/nl/vind-een-winkel/details/sport-2000-de-jonge-sport-stadskanaal/
A23: 18 | B23: EERSTE BENADERING | C23: Sport 2000 Sporthuis Winsum | D23: Winsum | E23: Noord | F23: Nog niet benaderd | G23: Nu | H23: Bellen, daarna mailen | J23: 0595-445199 | K23: info@sporthuiswinsum.nl | M23: =IF(L23="","",TODAY()-L23) | N23: Nog geen contact gevonden (sheet en mailbox info@). | O23: Breed sportassortiment (indicatief; niet gepubliceerd per winkel) | P23: Het Aanleg 6, 9951 SJ | Q23: Groningen | R23: Sport 2000 | U23: https://www.sport2000.nl/nl/vind-een-winkel/details/sport-2000-sporthuis-winsum/
A24: 19 | B24: EERSTE BENADERING | C24: Sport 2000 Mensink Denekamp | D24: Denekamp | E24: Oost | F24: Nog niet benaderd | G24: Nu | H24: Bellen, daarna mailen | J24: 0541-351388 | K24: info@mensinkschoenen.nl | M24: =IF(L24="","",TODAY()-L24) | N24: Nog geen contact gevonden (sheet en mailbox info@). | O24: Voetbal, Running, Indoor, Tennis, Training, Wandel, Teamwear | P24: Oldenzaalsestraat 12, 7591 GM | Q24: Overijssel | R24: Sport 2000 | U24: https://www.sport2000.nl/nl/vind-een-winkel/details/sport-2000-mensink-denekamp/
A25: 20 | B25: EERSTE BENADERING | C25: Sport 2000 Buitink Deventer | D25: Deventer | E25: Oost | F25: Nog niet benaderd | G25: Nu | H25: Bellen, daarna mailen | J25: 0570-650700 | K25: deventer@buitink-sport.nl | M25: =IF(L25="","",TODAY()-L25) | N25: Nog geen contact gevonden (sheet en mailbox info@). | O25: Tennis, Voetbal, Hockey, Harlopen, Fitness, Zaalsporten, Zwemmen, Schaatsen, Skeeleren, Teamkleding | P25: Flora 243-245, 7422 LP | Q25: Overijssel | R25: Sport 2000 | S25: Zusterwinkel Buitink Twello sluit volgens lokaal nieuws (voorsternieuws.nl); Deventer gaat door. | U25: https://www.sport2000.nl/nl/vind-een-winkel/details/sport-2000-buitink-deventer/
A26: 21 | B26: EERSTE BENADERING | C26: Sport 2000 Claus Doetinchem | D26: Doetinchem | E26: Oost | F26: Nog niet benaderd | G26: Nu | H26: Bellen, daarna mailen | J26: 0314-323139 | K26: klantenservice@claussport.nl | M26: =IF(L26="","",TODAY()-L26) | N26: Nog geen contact gevonden (sheet en mailbox info@). | O26: Hockey, Volleybal, Hardlopen, Voetballen, Wandel | P26: IJsselkade 10-12, 7001 AP | Q26: Gelderland | R26: Sport 2000 | U26: https://www.sport2000.nl/nl/vind-een-winkel/details/sport-2000-claus-doetinchem/
A27: 22 | B27: EERSTE BENADERING | C27: Sport 2000 Snelders Elst | D27: Elst | E27: Oost | F27: Nog niet benaderd | G27: Nu | H27: Bellen, daarna mailen | J27: 0481-374255 | K27: info@snelderssport.nl | M27: =IF(L27="","",TODAY()-L27) | N27: Nog geen contact gevonden (sheet en mailbox info@). | O27: Voetbal, tennis, hockey, running, fitness, bedrukking teamkleding. | P27: Dorpsstraat 26, 6661 EK | Q27: Gelderland | R27: Sport 2000 | U27: https://www.sport2000.nl/nl/vind-een-winkel/details/sport-2000-snelders-elst/
A28: 23 | B28: EERSTE BENADERING | C28: Sport 2000 Haverhals Badhoevedorp | D28: Badhoevedorp | E28: West | F28: Nog niet benaderd | G28: Nu | H28: Bellen, daarna mailen | J28: 020-6594705 | K28: info@sport2000haverhals.nl | M28: =IF(L28="","",TODAY()-L28) | N28: Nog geen contact gevonden (sheet en mailbox info@). | O28: hockey-, voetbal- en tennis | P28: Pa Verkuijllaan 33-35, 1171 EA | Q28: Noord-Holland | R28: Sport 2000 | U28: https://www.sport2000.nl/nl/vind-een-winkel/details/sport-2000-haverhals-badhoevedorp/
A29: 24 | B29: EERSTE BENADERING | C29: Sport 2000 Enkhuizen | D29: Enkhuizen | E29: West | F29: Nog niet benaderd | G29: Nu | H29: Bellen, daarna mailen | J29: 0228-325309 | K29: info@sport2000enkhuizen.nl | M29: =IF(L29="","",TODAY()-L29) | N29: Nog geen contact gevonden (sheet en mailbox info@). | O29: Running, Wandelen, Casual, Lifestyle, Service | P29: Westerstraat 126, 1601 AM | Q29: Noord-Holland | R29: Sport 2000 | U29: https://www.sport2000.nl/nl/vind-een-winkel/details/sport-2000-enkhuizen/
A30: 25 | B30: EERSTE BENADERING | C30: Sport 2000 Hilversum | D30: Hilversum | E30: West | F30: Nog niet benaderd | G30: Nu | H30: Bellen, daarna mailen | J30: 035-6833399 | K30: info@sport2000hilversum.nl | M30: =IF(L30="","",TODAY()-L30) | N30: Nog geen contact gevonden (sheet en mailbox info@). | O30: Voetbal, tennis, hockey, hardlopen fitness | P30: Kerkstraat 31, 1211 CK | Q30: Noord-Holland | R30: Sport 2000 | U30: https://www.sport2000.nl/nl/vind-een-winkel/details/sport-2000-hilversum/
A31: 26 | B31: EERSTE BENADERING | C31: Sport 2000 Soccer Center Ralph Sports Nieuwegein | D31: Nieuwegein | E31: West | F31: Nog niet benaderd | G31: Nu | H31: Bellen, daarna mailen | J31: 030-6022177 | K31: info@ralphsports.nl | M31: =IF(L31="","",TODAY()-L31) | N31: Nog geen contact gevonden (sheet en mailbox info@). | O31: Voetbal, casual | P31: 't Sluisje 10, 3438 AH | Q31: Utrecht | R31: Soccer Center | U31: https://www.sport2000.nl/nl/vind-een-winkel/details/sport-2000-soccer-center-ralph-sports-nieuwegein/
A32: 27 | B32: EERSTE BENADERING | C32: Sport 2000 De Lange Noordwijk | D32: Noordwijk | E32: West | F32: Nog niet benaderd | G32: Nu | H32: Bellen, daarna mailen | J32: 071-3612927 | K32: info@delangesport.nl | M32: =IF(L32="","",TODAY()-L32) | N32: Nog geen contact gevonden (sheet en mailbox info@). | O32: Voetbal, tennis, dans | P32: Molenstraat 16, 2201 KZ | Q32: Zuid-Holland | R32: Sport 2000 | U32: https://www.sport2000.nl/nl/vind-een-winkel/details/sport-2000-de-lange-noordwijk/
A33: 28 | B33: EERSTE BENADERING | C33: Sport 2000 Purmerend | D33: Purmerend | E33: West | F33: Nog niet benaderd | G33: Nu | H33: Bellen, daarna mailen | J33: 0299413630 | K33: info@sport2000purmerend.nl | M33: =IF(L33="","",TODAY()-L33) | N33: Nog geen contact gevonden (sheet en mailbox info@). | O33: Breed sportassortiment (indicatief; niet gepubliceerd per winkel) | P33: Dubbele Buurt 23-27, 1441 CT | Q33: Noord-Holland | R33: Sport 2000 | U33: https://www.sport2000.nl/nl/vind-een-winkel/details/sport-2000-purmerend/
A34: 29 | B34: EERSTE BENADERING | C34: Absolute Teamsport Rotterdam | D34: Rotterdam | E34: West | F34: Nog niet benaderd | G34: Nu | H34: Bellen, daarna mailen | J34: 010-2135594 | K34: info@sport2000rotterdam.nl | M34: =IF(L34="","",TODAY()-L34) | N34: Nog geen contact gevonden (sheet en mailbox info@). | O34: Voetbal, Casual, Hardlopen | P34: Hoogstraat 181, 3011 PM | Q34: Zuid-Holland | R34: Absolute Teamsport | U34: https://www.sport2000.nl/nl/vind-een-winkel/details/absolute-teamsport-rotterdam/
A35: 30 | B35: EERSTE BENADERING | C35: Sport 2000 Soccer Center Paul Pessel Utrecht | D35: Utrecht | E35: West | F35: Nog niet benaderd | G35: Nu | H35: Bellen, daarna mailen | J35: 030-2940300 | K35: info@paulpesselsport.nl | M35: =IF(L35="","",TODAY()-L35) | N35: Nog geen contact gevonden (sheet en mailbox info@). | O35: Voetbal, casual | P35: Croeselaan 183, 3521 BM | Q35: Utrecht | R35: Soccer Center | U35: https://www.sport2000.nl/nl/vind-een-winkel/details/sport-2000-soccer-center-paul-pessel-utrecht/
A36: 31 | B36: EERSTE BENADERING | C36: Sport 2000 Zeist | D36: Zeist | E36: West | F36: Nog niet benaderd | G36: Eerst intern | H36: Eerst vraag laten creëren door Anouk, dan benaderen | I36: Anouk (intern) | J36: 030-6933687 | K36: info@sport2000zeist.nl | M36: =IF(L36="","",TODAY()-L36) | N36: Nog geen contact gevonden (sheet en mailbox info@). | O36: Breed sportassortiment (indicatief; niet gepubliceerd per winkel) | P36: Voorheuvel 29, 3701 JA | Q36: Utrecht | R36: Sport 2000 | T36: Retail-sheet: 'EERST ANOUK VRAAG LATEN CREEEREN' | U36: https://www.sport2000.nl/nl/vind-een-winkel/details/sport-2000-zeist/
A37: 32 | B37: EERSTE BENADERING | C37: Sport 2000 Brabant Sports Boxtel | D37: Boxtel | E37: Zuid | F37: Nog niet benaderd | G37: Nu | H37: Bellen, daarna mailen | J37: 0411-671040 | K37: info@bsboxtel.nl | M37: =IF(L37="","",TODAY()-L37) | N37: Nog geen contact gevonden (sheet en mailbox info@). | O37: Voetbal, tennis, hockey | P37: Clarissenstraat 2 A, 5281 AZ | Q37: Noord-Brabant | R37: Sport 2000 | U37: https://www.sport2000.nl/nl/vind-een-winkel/details/sport-2000-brabant-sports-boxtel/
A38: 33 | B38: EERSTE BENADERING | C38: Sport 2000 Fairsports Oirschot | D38: Oirschot | E38: Zuid | F38: Nog niet benaderd | G38: Nu | H38: Bellen, daarna mailen | J38: 0499-573468 | K38: info@fairsports.nl | M38: =IF(L38="","",TODAY()-L38) | N38: Nog geen contact gevonden (sheet en mailbox info@). | O38: Voetbal, hockey, tennis, volleybal, korfbal, running, wandel, ,fitness, sportprijzen, textieldrukwerk, scheidsrechters | P38: Rijkesluisstraat 17, 5688 EC | Q38: Noord-Brabant | R38: Sport 2000 | U38: https://www.sport2000.nl/nl/vind-een-winkel/details/sport-2000-fairsports-oirschot/
A39: 34 | B39: EERSTE BENADERING | C39: Sport 2000 De Bruijn Panningen | D39: Panningen | E39: Zuid | F39: Nog niet benaderd | G39: Nu | H39: Bellen, daarna mailen | J39: 077-3071676 | K39: info@sport2000debruijn.nl | M39: =IF(L39="","",TODAY()-L39) | N39: Nog geen contact gevonden (sheet en mailbox info@). | O39: Voetbal, Tennis, Hardlopen, Wandelen, Badmode, Fitness Training, Handbal en Volleybal | P39: Ruijsstraat 23, 5981 CL | Q39: Limburg | R39: Sport 2000 | U39: https://www.sport2000.nl/nl/vind-een-winkel/details/sport-2000-de-bruijn-panningen/
A40: 35 | B40: EERSTE BENADERING | C40: Sport 2000 Soccer Center Posno Sport Roermond | D40: Roermond | E40: Zuid | F40: Nog niet benaderd | G40: Nu | H40: Bellen, daarna mailen | J40: 0475-311592 | K40: desportzaak@home.nl | M40: =IF(L40="","",TODAY()-L40) | N40: Nog geen contact gevonden (sheet en mailbox info@). | O40: Voetbal, casual | P40: Kruisherenstraat 15, 6041 HK | Q40: Limburg | R40: Soccer Center | U40: https://www.sport2000.nl/nl/vind-een-winkel/details/sport-2000-soccer-center-posno-sport-roermond/
...

Sheet Overzicht & stappen
B1: OVERZICHT & STAPPEN
B3: WAT MOET NU?
B4: OPVOLGEN | D4: BELLEN | F4: MAILEN | H4: WACHTEN
B5: =COUNTIF('Call-lijst'!$B$6:$B$54,"OPVOLGEN") | D5: =COUNTIF('Call-lijst'!$B$6:$B$54,"BELLEN") | F5: =COUNTIF('Call-lijst'!$B$6:$B$54,"MAILEN") | H5: =COUNTIF('Call-lijst'!$B$6:$B$54,"WACHTEN")
B8: EERSTE BENADERING | D8: LATER | F8: KLANT | H8: NIET BENADEREN
B9: =COUNTIF('Call-lijst'!$B$6:$B$54,"EERSTE BENADERING") | D9: =COUNTIF('Call-lijst'!$B$6:$B$54,"LATER") | F9: =COUNTIF('Call-lijst'!$B$6:$B$54,"KLANT") | H9: =COUNTIF('Call-lijst'!$B$6:$B$54,"NIET BENADEREN")
B13: PER REGIO
B14: Regio | C14: OPVOLGEN | D14: BELLEN | E14: MAILEN | F14: WACHTEN | G14: EERSTE BENADERING | H14: LATER | I14: KLANT | J14: NIET BENADEREN
B15: West | C15: =COUNTIFS('Call-lijst'!$E$6:$E$54,$B15,'Call-lijst'!$B$6:$B$54,"OPVOLGEN") | D15: =COUNTIFS('Call-lijst'!$E$6:$E$54,$B15,'Call-lijst'!$B$6:$B$54,"BELLEN") | E15: =COUNTIFS('Call-lijst'!$E$6:$E$54,$B15,'Call-lijst'!$B$6:$B$54,"MAILEN") | F15: =COUNTIFS('Call-lijst'!$E$6:$E$54,$B15,'Call-lijst'!$B$6:$B$54,"WACHTEN") | G15: =COUNTIFS('Call-lijst'!$E$6:$E$54,$B15,'Call-lijst'!$B$6:$B$54,"EERSTE BENADERING") | H15: =COUNTIFS('Call-lijst'!$E$6:$E$54,$B15,'Call-lijst'!$B$6:$B$54,"LATER") | I15: =COUNTIFS('Call-lijst'!$E$6:$E$54,$B15,'Call-lijst'!$B$6:$B$54,"KLANT") | J15: =COUNTIFS('Call-lijst'!$E$6:$E$54,$B15,'Call-lijst'!$B$6:$B$54,"NIET BENADEREN")
B16: Midden | C16: =COUNTIFS('Call-lijst'!$E$6:$E$54,$B16,'Call-lijst'!$B$6:$B$54,"OPVOLGEN") | D16: =COUNTIFS('Call-lijst'!$E$6:$E$54,$B16,'Call-lijst'!$B$6:$B$54,"BELLEN") | E16: =COUNTIFS('Call-lijst'!$E$6:$E$54,$B16,'Call-lijst'!$B$6:$B$54,"MAILEN") | F16: =COUNTIFS('Call-lijst'!$E$6:$E$54,$B16,'Call-lijst'!$B$6:$B$54,"WACHTEN") | G16: =COUNTIFS('Call-lijst'!$E$6:$E$54,$B16,'Call-lijst'!$B$6:$B$54,"EERSTE BENADERING") | H16: =COUNTIFS('Call-lijst'!$E$6:$E$54,$B16,'Call-lijst'!$B$6:$B$54,"LATER") | I16: =COUNTIFS('Call-lijst'!$E$6:$E$54,$B16,'Call-lijst'!$B$6:$B$54,"KLANT") | J16: =COUNTIFS('Call-lijst'!$E$6:$E$54,$B16,'Call-lijst'!$B$6:$B$54,"NIET BENADEREN")
B17: Oost | C17: =COUNTIFS('Call-lijst'!$E$6:$E$54,$B17,'Call-lijst'!$B$6:$B$54,"OPVOLGEN") | D17: =COUNTIFS('Call-lijst'!$E$6:$E$54,$B17,'Call-lijst'!$B$6:$B$54,"BELLEN") | E17: =COUNTIFS('Call-lijst'!$E$6:$E$54,$B17,'Call-lijst'!$B$6:$B$54,"MAILEN") | F17: =COUNTIFS('Call-lijst'!$E$6:$E$54,$B17,'Call-lijst'!$B$6:$B$54,"WACHTEN") | G17: =COUNTIFS('Call-lijst'!$E$6:$E$54,$B17,'Call-lijst'!$B$6:$B$54,"EERSTE BENADERING") | H17: =COUNTIFS('Call-lijst'!$E$6:$E$54,$B17,'Call-lijst'!$B$6:$B$54,"LATER") | I17: =COUNTIFS('Call-lijst'!$E$6:$E$54,$B17,'Call-lijst'!$B$6:$B$54,"KLANT") | J17: =COUNTIFS('Call-lijst'!$E$6:$E$54,$B17,'Call-lijst'!$B$6:$B$54,"NIET BENADEREN")
B18: Zuid | C18: =COUNTIFS('Call-lijst'!$E$6:$E$54,$B18,'Call-lijst'!$B$6:$B$54,"OPVOLGEN") | D18: =COUNTIFS('Call-lijst'!$E$6:$E$54,$B18,'Call-lijst'!$B$6:$B$54,"BELLEN") | E18: =COUNTIFS('Call-lijst'!$E$6:$E$54,$B18,'Call-lijst'!$B$6:$B$54,"MAILEN") | F18: =COUNTIFS('Call-lijst'!$E$6:$E$54,$B18,'Call-lijst'!$B$6:$B$54,"WACHTEN") | G18: =COUNTIFS('Call-lijst'!$E$6:$E$54,$B18,'Call-lijst'!$B$6:$B$54,"EERSTE BENADERING") | H18: =COUNTIFS('Call-lijst'!$E$6:$E$54,$B18,'Call-lijst'!$B$6:$B$54,"LATER") | I18: =COUNTIFS('Call-lijst'!$E$6:$E$54,$B18,'Call-lijst'!$B$6:$B$54,"KLANT") | J18: =COUNTIFS('Call-lijst'!$E$6:$E$54,$B18,'Call-lijst'!$B$6:$B$54,"NIET BENADEREN")
B19: Noord | C19: =COUNTIFS('Call-lijst'!$E$6:$E$54,$B19,'Call-lijst'!$B$6:$B$54,"OPVOLGEN") | D19: =COUNTIFS('Call-lijst'!$E$6:$E$54,$B19,'Call-lijst'!$B$6:$B$54,"BELLEN") | E19: =COUNTIFS('Call-lijst'!$E$6:$E$54,$B19,'Call-lijst'!$B$6:$B$54,"MAILEN") | F19: =COUNTIFS('Call-lijst'!$E$6:$E$54,$B19,'Call-lijst'!$B$6:$B$54,"WACHTEN") | G19: =COUNTIFS('Call-lijst'!$E$6:$E$54,$B19,'Call-lijst'!$B$6:$B$54,"EERSTE BENADERING") | H19: =COUNTIFS('Call-lijst'!$E$6:$E$54,$B19,'Call-lijst'!$B$6:$B$54,"LATER") | I19: =COUNTIFS('Call-lijst'!$E$6:$E$54,$B19,'Call-lijst'!$B$6:$B$54,"KLANT") | J19: =COUNTIFS('Call-lijst'!$E$6:$E$54,$B19,'Call-lijst'!$B$6:$B$54,"NIET BENADEREN")
B22: DE STAPPEN (zo werken jullie legenda en de lijst samen)
B23: Stap | C23: Actie op de lijst | D23: Wat doe je? | H23: Status in legenda
B24: 1 | C24: EERSTE BENADERING | D24: Nog geen contact. Bel de winkel, vraag naar de inkoper, mail daarna de uitleg met catalogus. | H24: Nog niet benaderd
B25: 2 | C25: Gebeld / gemaild | D25: Eerste contact is geweest. Wacht op reactie of terugbellen. | H25: Gemaild / Gebeld · Bellen ons
B26: 3 | C26: OPVOLGEN of reminder | D26: Geen reactie na ongeveer een week of maand: reminder mailen en nog een keer bellen. | H26: Reminder gestuurd · Bellen
B27: 4 | C27: Positieve lead | D27: Interesse. Samples opsturen, lead in Bigin zetten (potentiële klant). | H27: Positieve lead
B28: 5 | C28: KLANT | D28: Eerste bestelling. Relatie onderhouden en herbestelling. | H28: Klant (actief)
B29: Zijpad | C29: LATER | D29: Nu geen interesse. Staat een moment genoemd (bijvoorbeeld 'januari'), dan dat moment bellen. | H29: Nu geen interesse, later opnieuw benaderen
B30: Zijpad | C30: NIET BENADEREN | D30: Nooit meer benaderen. Niet bellen, niet mailen. | H30: Nooit meer benaderen
B32: KLEURENLEGENDA (kleur = wat je nu moet doen; de kolom Status blijft jullie eigen woorden)
B33: OPVOLGEN | C33: Reminder of feedback vragen
B34: BELLEN | C34: Nu bellen
B35: MAILEN | C35: Nu mailen
B36: WACHTEN | C36: Zij zijn aan zet
B37: EERSTE BENADERING | C37: Bellen, daarna mailen
B38: LATER | C38: Op het genoemde moment
B39: KLANT | C39: Relatie onderhouden
B40: NIET BENADEREN | C40: Nooit meer benaderen

Sheet Uitgesloten (bestaat niet)
A1: UITGESLOTEN: staan in jullie sheets, maar niet (meer) op sport2000.nl
A3: Naam (uit jullie sheet) | B3: Plaats | C3: Bron | D3: Status in jullie sheet | E3: Notitie in jullie sheet | F3: Reden uitsluiting
A4: SPORT 2000 Alkmaar | B4: Alkmaar | C4: Retail-sheet | D4: Nu geen interesse, later opnieuw benaderen | F4: Staat niet op de officiële lijst van sport2000.nl (gecontroleerd 27-10-2026)
A5: SPORT 2000 Axel | B5: Axel | C5: Retail-sheet | D5: Bestaat niet | F5: Bestaat niet meer (jullie eigen markering); ook niet op sport2000.nl
A6: SPORT 2000 Bodegraven | B6: Bodegraven | C6: Retail-sheet | D6: Bestaat niet | E6: Bestaat niet meer | F6: Bestaat niet meer (jullie eigen markering); ook niet op sport2000.nl
A7: SPORT 2000 Broek op Langedijk | B7: Broek op Langedijk | C7: Retail-sheet + Timo's lijst | D7: Nooit meer benaderen | F7: Niet meer op sport2000.nl: winkelpagina geeft 404 (27-10-2026).
A8: SPORT 2000 Hellevoetsluis | B8: Hellevoetsluis | C8: Retail-sheet | D8: Nooit meer benaderen | F8: Staat niet op de officiële lijst van sport2000.nl (gecontroleerd 27-10-2026)
A9: SPORT 2000 Oud-Beijerland | B9: Oud-Beijerland | C9: Retail-sheet + Timo's lijst | D9: Nooit meer benaderen | F9: Niet meer op sport2000.nl: winkelpagina geeft 404 (27-10-2026).
A10: SPORT 2000 Renesse | B10: Renesse | C10: Retail-sheet | D10: Bestaat niet | E10: Bestaat niet meer | F10: Bestaat niet meer (jullie eigen markering); ook niet op sport2000.nl
A11: SPORT 2000 Roelofarendsveen | B11: Roelofarendsveen | C11: Retail-sheet | D11: Nooit meer benaderen | F11: Staat niet op de officiële lijst van sport2000.nl (gecontroleerd 27-10-2026)
A12: SPORT 2000 Rosmalen | B12: Rosmalen | C12: Retail-sheet | D12: Nooit meer benaderen | F12: Staat niet op de officiële lijst van sport2000.nl (gecontroleerd 27-10-2026)
A13: SPORT 2000 Veghel | B13: Veghel | C13: Retail-sheet | D13: Nooit meer benaderen | F13: Staat niet op de officiële lijst van sport2000.nl (gecontroleerd 27-10-2026)
A14: SPORT 2000 's-Gravenzande | B14: 's-Gravenzande | C14: Retail-sheet | D14: (geen) | F14: Staat niet op de officiële lijst van sport2000.nl (gecontroleerd 27-10-2026)
A15: SPORT 2000 Amersfoort | B15: Amersfoort | C15: Retail-sheet | D15: (geen) | F15: Staat niet op de officiële lijst van sport2000.nl (gecontroleerd 27-10-2026)
A16: SPORT 2000 Beverwijk | B16: Beverwijk | C16: Retail-sheet | D16: (geen) | F16: Staat niet op de officiële lijst van sport2000.nl (gecontroleerd 27-10-2026)
A17: SPORT 2000 Delft | B17: Delft | C17: Retail-sheet | D17: (geen) | F17: Staat niet op de officiële lijst van sport2000.nl (gecontroleerd 27-10-2026)
A18: SPORT 2000 Dokkum | B18: Dokkum | C18: Retail-sheet | D18: (geen) | F18: Staat niet op de officiële lijst van sport2000.nl (gecontroleerd 27-10-2026)
A19: SPORT 2000 Dordrecht | B19: Dordrecht | C19: Retail-sheet | D19: (geen) | F19: Staat niet op de officiële lijst van sport2000.nl (gecontroleerd 27-10-2026)
A20: SPORT 2000 Driebergen-Rijsenburg | B20: Driebergen-Rijsenburg | C20: Retail-sheet | D20: (geen) | F20: Staat niet op de officiële lijst van sport2000.nl (gecontroleerd 27-10-2026)
A21: SPORT 2000 Gouda | B21: Gouda | C21: Retail-sheet | D21: (geen) | F21: Staat niet op de officiële lijst van sport2000.nl (gecontroleerd 27-10-2026)
A22: SPORT 2000 Haaksbergen | B22: Haaksbergen | C22: Retail-sheet | D22: (geen) | F22: Staat niet op de officiële lijst van sport2000.nl (gecontroleerd 27-10-2026)
... A41: SPORT 2000 Zoetermeer | B41: Zoetermeer | C41: Retail-sheet | D41: (geen) | F41: Staat niet op de officiële lijst van sport2000.nl (gecontroleerd 27-10-2026)

Sheet Toelichting
A1: Bronnen en aannames
A2: Bronnen
A3: 1. Officiële winkelzoeker en sitemap van sport2000.nl (27-10-2026): 49 Nederlandse winkels. Naam, adres, telefoon en e-mail per winkelpagina.
A4: 2. 'Cold acquisition B2B - HÏ Grip' (Google Sheet), tabbladen RETAIL ALGEMEEN en TIMOS LIJST: status (rijkleur), notities, contactpersonen, specialisaties.
A5: 3. Vault: Actieve Samenwerkingen (B2B Klanten) bevestigt Naaldwijk en Nootdorp als klant.
A6: 4. Mailbox info@higrip.nl (alleen gelezen, niets gewijzigd), 27-10-2026: Spijkenisse, Voorburg, Leiderdorp, Olympia Veldhoven, Akwi, Almere en Schagen zijn hiermee aangevuld.
A8: Beperkingen
A9: - Alleen mail die in info@ staat of waar info@ in cc zat is gevonden. Mail van Tigo of anderen zonder cc naar info@ ontbreekt.
A10: - Telefoongesprekken staan alleen als een mail ze noemt. Een leeg veld bij Laatste contact betekent: datum onbekend.
A11: - 'Eerste benadering' betekent: geen contact gevonden in de sheet en in info@. Het bewijst niet dat er nooit contact is geweest.
A13: Aannames
A14: - 'mailen' in Timo's lijst en de groene kleur 'Mailen' lees ik als: nog te mailen.
... A23: - Vul Laatste contact in na elk gesprek of mail: Dagen geleden wordt oranje na 30 dagen en rood na 60 dagen.
